Workbook

Sheet White_exposure
A1: Metrics | B1: Exposed population | D1: Downscaling | F1: AQM
B2: SSP2 | C2: 3.93 | D2: Statistical | E2: 3.93 | F2: WRF-Chem | G2: 6.26
F3: InMAP | G3: 3.93
F4: ISRM | G4: 3.81
D5: Equity | E5: 3.38 | F5: WRF-Chem | G5: 6.22
F6: InMAP | G6: 3.38
F7: ISRM | G7: 3.52
B8: SSP3 | C8: 3.94 | D8: Statistical | E8: 3.94 | F8: WRF-Chem | G8: 6.26
F9: InMAP | G9: 3.94
F10: ISRM | G10: 3.81
D11: Equity | E11: 3.38 | F11: WRF-Chem | G11: 6.22
F12: InMAP | G12: 3.38
F13: ISRM | G13: 3.52
B14: SSP5 | C14: 3.93 | D14: Statistical | E14: 3.93 | F14: WRF-Chem | G14: 6.26
F15: InMAP | G15: 3.93
F16: ISRM | G16: 3.81
D17: Equity | E17: 3.38 | F17: WRF-Chem | G17: 6.22
F18: InMAP | G18: 3.38
F19: ISRM | G19: 3.52

Sheet Black_exposure
A1: Metrics | B1: Exposed population | D1: Downscaling | F1: AQM
B2: SSP2 | C2: 4.52 | D2: Statistical | E2: 4.52 | F2: WRF-Chem | G2: 6.81
F3: InMAP | G3: 4.52
F4: ISRM | G4: 4.34
D5: Equity | E5: 3.56 | F5: WRF-Chem | G5: 6.59
F6: InMAP | G6: 3.56
F7: ISRM | G7: 3.61
B8: SSP3 | C8: 4.53 | D8: Statistical | E8: 4.53 | F8: WRF-Chem | G8: 6.82
F9: InMAP | G9: 4.53
F10: ISRM | G10: 4.34
D11: Equity | E11: 3.56 | F11: WRF-Chem | G11: 6.59
F12: InMAP | G12: 3.56
F13: ISRM | G13: 3.61
B14: SSP5 | C14: 4.52 | D14: Statistical | E14: 4.52 | F14: WRF-Chem | G14: 6.81
F15: InMAP | G15: 4.52
F16: ISRM | G16: 4.34
D17: Equity | E17: 3.56 | F17: WRF-Chem | G17: 6.58
F18: InMAP | G18: 3.56
F19: ISRM | G19: 3.6

Sheet Disparity_exposure
A1: nonWhite_minus_White
A2: =Black_exposure!C2-White_exposure!C2 -> 0.59 | B2: =A2 -> 0.59 | C2: =Black_exposure!E2-White_exposure!E2 -> 0.59 | D2: =C2 -> 0.59 | E2: =Black_exposure!G2-White_exposure!G2 -> 0.55 | F2: =E2 -> 0.55
A3: =Black_exposure!C3-White_exposure!C3 -> 0 | B3: =IF(A3=0,B2,A3) -> 0.59 | C3: =Black_exposure!E3-White_exposure!E3 -> 0 | D3: =IF(C3=0,D2,C3) -> 0.59 | E3: =Black_exposure!G3-White_exposure!G3 -> 0.59 | F3: =IF(E3=0,F2,E3) -> 0.59
A4: =Black_exposure!C4-White_exposure!C4 -> 0 | B4: =IF(A4=0,B3,A4) -> 0.59 | C4: =Black_exposure!E4-White_exposure!E4 -> 0 | D4: =IF(C4=0,D3,C4) -> 0.59 | E4: =Black_exposure!G4-White_exposure!G4 -> 0.53 | F4: =E4 -> 0.53
A5: =Black_exposure!C5-White_exposure!C5 -> 0 | B5: =IF(A5=0,B4,A5) -> 0.59 | C5: =Black_exposure!E5-White_exposure!E5 -> 0.18 | D5: =IF(C5=0,D4,C5) -> 0.18 | E5: =Black_exposure!G5-White_exposure!G5 -> 0.37 | F5: =IF(E5=0,F4,E5) -> 0.37
A6: =Black_exposure!C6-White_exposure!C6 -> 0 | B6: =IF(A6=0,B5,A6) -> 0.59 | C6: =Black_exposure!E6-White_exposure!E6 -> 0 | D6: =IF(C6=0,D5,C6) -> 0.18 | E6: =Black_exposure!G6-White_exposure!G6 -> 0.18 | F6: =E6 -> 0.18
A7: =Black_exposure!C7-White_exposure!C7 -> 0 | B7: =IF(A7=0,B6,A7) -> 0.59 | C7: =Black_exposure!E7-White_exposure!E7 -> 0 | D7: =IF(C7=0,D6,C7) -> 0.18 | E7: =Black_exposure!G7-White_exposure!G7 -> 0.09 | F7: =IF(E7=0,F6,E7) -> 0.09
A8: =Black_exposure!C8-White_exposure!C8 -> 0.59 | B8: =IF(A8=0,B7,A8) -> 0.59 | C8: =Black_exposure!E8-White_exposure!E8 -> 0.59 | D8: =IF(C8=0,D7,C8) -> 0.59 | E8: =Black_exposure!G8-White_exposure!G8 -> 0.56 | F8: =E8 -> 0.56
A9: =Black_exposure!C9-White_exposure!C9 -> 0 | B9: =IF(A9=0,B8,A9) -> 0.59 | C9: =Black_exposure!E9-White_exposure!E9 -> 0 | D9: =IF(C9=0,D8,C9) -> 0.59 | E9: =Black_exposure!G9-White_exposure!G9 -> 0.59 | F9: =IF(E9=0,F8,E9) -> 0.59
A10: =Black_exposure!C10-White_exposure!C10 -> 0 | B10: =IF(A10=0,B9,A10) -> 0.59 | C10: =Black_exposure!E10-White_exposure!E10 -> 0 | D10: =IF(C10=0,D9,C10) -> 0.59 | E10: =Black_exposure!G10-White_exposure!G10 -> 0.53 | F10: =E10 -> 0.53
A11: =Black_exposure!C11-White_exposure!C11 -> 0 | B11: =IF(A11=0,B10,A11) -> 0.59 | C11: =Black_exposure!E11-White_exposure!E11 -> 0.18 | D11: =IF(C11=0,D10,C11) -> 0.18 | E11: =Black_exposure!G11-White_exposure!G11 -> 0.37 | F11: =IF(E11=0,F10,E11) -> 0.37
A12: =Black_exposure!C12-White_exposure!C12 -> 0 | B12: =IF(A12=0,B11,A12) -> 0.59 | C12: =Black_exposure!E12-White_exposure!E12 -> 0 | D12: =IF(C12=0,D11,C12) -> 0.18 | E12: =Black_exposure!G12-White_exposure!G12 -> 0.18 | F12: =E12 -> 0.18
A13: =Black_exposure!C13-White_exposure!C13 -> 0 | B13: =IF(A13=0,B12,A13) -> 0.59 | C13: =Black_exposure!E13-White_exposure!E13 -> 0 | D13: =IF(C13=0,D12,C13) -> 0.18 | E13: =Black_exposure!G13-White_exposure!G13 -> 0.09 | F13: =IF(E13=0,F12,E13) -> 0.09
A14: =Black_exposure!C14-White_exposure!C14 -> 0.59 | B14: =IF(A14=0,B13,A14) -> 0.59 | C14: =Black_exposure!E14-White_exposure!E14 -> 0.59 | D14: =IF(C14=0,D13,C14) -> 0.59 | E14: =Black_exposure!G14-White_exposure!G14 -> 0.55 | F14: =E14 -> 0.55
A15: =Black_exposure!C15-White_exposure!C15 -> 0 | B15: =IF(A15=0,B14,A15) -> 0.59 | C15: =Black_exposure!E15-White_exposure!E15 -> 0 | D15: =IF(C15=0,D14,C15) -> 0.59 | E15: =Black_exposure!G15-White_exposure!G15 -> 0.59 | F15: =IF(E15=0,F14,E15) -> 0.59
A16: =Black_exposure!C16-White_exposure!C16 -> 0 | B16: =IF(A16=0,B15,A16) -> 0.59 | C16: =Black_exposure!E16-White_exposure!E16 -> 0 | D16: =IF(C16=0,D15,C16) -> 0.59 | E16: =Black_exposure!G16-White_exposure!G16 -> 0.53 | F16: =E16 -> 0.53
A17: =Black_exposure!C17-White_exposure!C17 -> 0 | B17: =IF(A17=0,B16,A17) -> 0.59 | C17: =Black_exposure!E17-White_exposure!E17 -> 0.18 | D17: =IF(C17=0,D16,C17) -> 0.18 | E17: =Black_exposure!G17-White_exposure!G17 -> 0.36 | F17: =IF(E17=0,F16,E17) -> 0.36
A18: =Black_exposure!C18-White_exposure!C18 -> 0 | B18: =IF(A18=0,B17,A18) -> 0.59 | C18: =Black_exposure!E18-White_exposure!E18 -> 0 | D18: =IF(C18=0,D17,C18) -> 0.18 | E18: =Black_exposure!G18-White_exposure!G18 -> 0.18 | F18: =E18 -> 0.18
A19: =Black_exposure!C19-White_exposure!C19 -> 0 | B19: =IF(A19=0,B18,A19) -> 0.59 | C19: =Black_exposure!E19-White_exposure!E19 -> 0 | D19: =IF(C19=0,D18,C19) -> 0.18 | E19: =Black_exposure!G19-White_exposure!G19 -> 0.08 | F19: =IF(E19=0,F18,E19) -> 0.08

Sheet White_deaths
A1: Metrics | B1: Exposed population | D1: Downscaling | F1: AQM | H1: Baseline mortality rates | J1: Relative risks
B2: SSP2 | C2: 49 | D2: Statistical | E2: 49 | F2: WRF-Chem | G2: 78 | H2: Uniform | I2: 78 | J2: Uniform | K2: 78
J3: Different | K3: 82
H4: Different | I4: 82 | J4: Uniform | K4: 82
J5: Different | K5: 86
F6: InMAP | G6: 49 | H6: Uniform | I6: 49 | J6: Uniform | K6: 49
J7: Different | K7: 51
H8: Different | I8: 82 | J8: Uniform | K8: 51
J9: Different | K9: 53
F10: ISRM | G10: 47 | H10: Uniform | I10: 47 | J10: Uniform | K10: 47
J11: Different | K11: 49
H12: Different | I12: 49 | J12: Uniform | K12: 49
J13: Different | K13: 52
D14: Equity | E14: 43 | F14: WRF-Chem | G14: 78 | H14: Uniform | I14: 78 | J14: Uniform | K14: 78
J15: Different | K15: 81
H16: Different | I16: 82 | J16: Uniform | K16: 82
J17: Different | K17: 85
F18: InMAP | G18: 43 | H18: Uniform | I18: 43 | J18: Uniform | K18: 43
J19: Different | K19: 45
H20: Different | I20: 45 | J20: Uniform | K20: 45
J21: Different | K21: 47
F22: ISRM | G22: 44 | H22: Uniform | I22: 44 | J22: Uniform | K22: 44
J23: Different | K23: 46
H24: Different | I24: 47 | J24: Uniform | K24: 47
J25: Different | K25: 49
B26: SSP3 | C26: 39 | D26: Statistical | E26: 39 | F26: WRF-Chem | G26: 63 | H26: Uniform | I26: 63 | J26: Uniform | K26: 63
J27: Different | K27: 66
H28: Different | I28: 66 | J28: Uniform | K28: 66
J29: Different | K29: 69
F30: InMAP | G30: 39 | H30: Uniform | I30: 39 | J30: Uniform | K30: 39
J31: Different | K31: 41
H32: Different | I32: 41 | J32: Uniform | K32: 41
J33: Different | K33: 43
F34: ISRM | G34: 38 | H34: Uniform | I34: 38 | J34: Uniform | K34: 38
J35: Different | K35: 40
H36: Different | I36: 40 | J36: Uniform | K36: 40
J37: Different | K37: 42
D38: Equity | E38: 35 | F38: WRF-Chem | G38: 63 | H38: Uniform | I38: 63 | J38: Uniform | K38: 63
J39: Different | K39: 66
H40: Different | I40: 66 | J40: Uniform | K40: 66
...

Sheet Black_deaths
A1: Metrics | B1: Exposed population | D1: Downscaling | F1: AQM | H1: Baseline mortality rates | J1: Relative risks
B2: SSP2 | C2: 16 | D2: Statistical | E2: 16 | F2: WRF-Chem | G2: 24 | H2: Uniform | I2: 24 | J2: Uniform | K2: 24
J3: Different | K3: 74
H4: Different | I4: 26 | J4: Uniform | K4: 26
J5: Different | K5: 80
F6: InMAP | G6: 16 | H6: Uniform | I6: 16 | J6: Uniform | K6: 16
J7: Different | K7: 49
H8: Different | I8: 17 | J8: Uniform | K8: 17
J9: Different | K9: 53
F10: ISRM | G10: 15 | H10: Uniform | I10: 15 | J10: Uniform | K10: 15
J11: Different | K11: 47
H12: Different | I12: 16 | J12: Uniform | K12: 16
J13: Different | K13: 51
D14: Equity | E14: 13 | F14: WRF-Chem | G14: 23 | H14: Uniform | I14: 23 | J14: Uniform | K14: 23
J15: Different | K15: 72
H16: Different | I16: 25 | J16: Uniform | K16: 25
J17: Different | K17: 78
F18: InMAP | G18: 13 | H18: Uniform | I18: 13 | J18: Uniform | K18: 13
J19: Different | K19: 40
H20: Different | I20: 14 | J20: Uniform | K20: 14
J21: Different | K21: 43
F22: ISRM | G22: 13 | H22: Uniform | I22: 13 | J22: Uniform | K22: 13
J23: Different | K23: 40
H24: Different | I24: 14 | J24: Uniform | K24: 14
J25: Different | K25: 44
B26: SSP3 | C26: 13 | D26: Statistical | E26: 13 | F26: WRF-Chem | G26: 19 | H26: Uniform | I26: 19 | J26: Uniform | K26: 19
J27: Different | K27: 59
H28: Different | I28: 21 | J28: Uniform | K28: 21
J29: Different | K29: 66
F30: InMAP | G30: 13 | H30: Uniform | I30: 13 | J30: Uniform | K30: 13
J31: Different | K31: 39
H32: Different | I32: 14 | J32: Uniform | K32: 14
J33: Different | K33: 44
F34: ISRM | G34: 12 | H34: Uniform | I34: 12 | J34: Uniform | K34: 12
J35: Different | K35: 38
H36: Different | I36: 13 | J36: Uniform | K36: 13
J37: Different | K37: 42
D38: Equity | E38: 10 | F38: WRF-Chem | G38: 19 | H38: Uniform | I38: 19 | J38: Uniform | K38: 19
J39: Different | K39: 58
H40: Different | I40: 21 | J40: Uniform | K40: 21
...

Sheet Disparity_deaths
A1: nonWhite_minus_White
A2: =Black_deaths!C2-White_deaths!C2 -> -33 | B2: =A2 -> -33 | C2: =Black_deaths!E2-White_deaths!E2 -> -33 | D2: =C2 -> -33 | E2: =Black_deaths!G2-White_deaths!G2 -> -54 | F2: =E2 -> -54 | G2: =Black_deaths!I2-White_deaths!I2 -> -54 | H2: =G2 -> -54 | I2: =Black_deaths!K2-White_deaths!K2 -> -54 | J2: =I2 -> -54
A3: =Black_deaths!C3-White_deaths!C3 -> #VALUE! | B3: =IF(A3=0,B2,A3) -> #VALUE! | C3: =Black_deaths!E3-White_deaths!E3 -> #VALUE! | D3: =IF(C3=0,D2,C3) -> #VALUE! | E3: =Black_deaths!G3-White_deaths!G3 -> #VALUE! | F3: =IF(E3=0,F2,E3) -> #VALUE! | G3: =Black_deaths!I3-White_deaths!I3 -> #VALUE! | H3: =IF(G3=0,H2,G3) -> #VALUE! | I3: =Black_deaths!K3-White_deaths!K3 -> -8 | J3: =IF(I3=0,J2,I3) -> -8
A4: =Black_deaths!C4-White_deaths!C4 -> #VALUE! | B4: =IF(A4=0,B3,A4) -> #VALUE! | C4: =Black_deaths!E4-White_deaths!E4 -> #VALUE! | D4: =IF(C4=0,D3,C4) -> #VALUE! | E4: =Black_deaths!G4-White_deaths!G4 -> #VALUE! | F4: =IF(E4=0,F3,E4) -> #VALUE! | G4: =Black_deaths!I4-White_deaths!I4 -> -56 | H4: =IF(G4=0,H3,G4) -> -56 | I4: =Black_deaths!K4-White_deaths!K4 -> -56 | J4: =I4 -> -56
A5: =Black_deaths!C5-White_deaths!C5 -> #VALUE! | B5: =IF(A5=0,B4,A5) -> #VALUE! | C5: =Black_deaths!E5-White_deaths!E5 -> #VALUE! | D5: =IF(C5=0,D4,C5) -> #VALUE! | E5: =Black_deaths!G5-White_deaths!G5 -> #VALUE! | F5: =IF(E5=0,F4,E5) -> #VALUE! | G5: =Black_deaths!I5-White_deaths!I5 -> #VALUE! | H5: =IF(G5=0,H4,G5) -> #VALUE! | I5: =Black_deaths!K5-White_deaths!K5 -> -6 | J5: =IF(I5=0,J4,I5) -> -6
A6: =Black_deaths!C6-White_deaths!C6 -> #VALUE! | B6: =IF(A6=0,B5,A6) -> #VALUE! | C6: =Black_deaths!E6-White_deaths!E6 -> #VALUE! | D6: =IF(C6=0,D5,C6) -> #VALUE! | E6: =Black_deaths!G6-White_deaths!G6 -> -33 | F6: =IF(E6=0,F5,E6) -> -33 | G6: =Black_deaths!I6-White_deaths!I6 -> -33 | H6: =IF(G6=0,H5,G6) -> -33 | I6: =Black_deaths!K6-White_deaths!K6 -> -33 | J6: =I6 -> -33
A7: =Black_deaths!C7-White_deaths!C7 -> #VALUE! | B7: =IF(A7=0,B6,A7) -> #VALUE! | C7: =Black_deaths!E7-White_deaths!E7 -> #VALUE! | D7: =IF(C7=0,D6,C7) -> #VALUE! | E7: =Black_deaths!G7-White_deaths!G7 -> #VALUE! | F7: =IF(E7=0,F6,E7) -> #VALUE! | G7: =Black_deaths!I7-White_deaths!I7 -> #VALUE! | H7: =IF(G7=0,H6,G7) -> #VALUE! | I7: =Black_deaths!K7-White_deaths!K7 -> -2 | J7: =IF(I7=0,J6,I7) -> -2
A8: =Black_deaths!C8-White_deaths!C8 -> #VALUE! | B8: =IF(A8=0,B7,A8) -> #VALUE! | C8: =Black_deaths!E8-White_deaths!E8 -> #VALUE! | D8: =IF(C8=0,D7,C8) -> #VALUE! | E8: =Black_deaths!G8-White_deaths!G8 -> #VALUE! | F8: =IF(E8=0,F7,E8) -> #VALUE! | G8: =Black_deaths!I8-White_deaths!I8 -> -65 | H8: =IF(G8=0,H7,G8) -> -65 | I8: =Black_deaths!K8-White_deaths!K8 -> -34 | J8: =I8 -> -34
A9: =Black_deaths!C9-White_deaths!C9 -> #VALUE! | B9: =IF(A9=0,B8,A9) -> #VALUE! | C9: =Black_deaths!E9-White_deaths!E9 -> #VALUE! | D9: =IF(C9=0,D8,C9) -> #VALUE! | E9: =Black_deaths!G9-White_deaths!G9 -> #VALUE! | F9: =IF(E9=0,F8,E9) -> #VALUE! | G9: =Black_deaths!I9-White_deaths!I9 -> #VALUE! | H9: =IF(G9=0,H8,G9) -> #VALUE! | I9: =Black_deaths!K9-White_deaths!K9 -> 0 | J9: =IF(I9=0,J8,I9) -> -34
A10: =Black_deaths!C10-White_deaths!C10 -> #VALUE! | B10: =IF(A10=0,B9,A10) -> #VALUE! | C10: =Black_deaths!E10-White_deaths!E10 -> #VALUE! | D10: =IF(C10=0,D9,C10) -> #VALUE! | E10: =Black_deaths!G10-White_deaths!G10 -> -32 | F10: =IF(E10=0,F9,E10) -> -32 | G10: =Black_deaths!I10-White_deaths!I10 -> -32 | H10: =IF(G10=0,H9,G10) -> -32 | I10: =Black_deaths!K10-White_deaths!K10 -> -32 | J10: =I10 -> -32
A11: =Black_deaths!C11-White_deaths!C11 -> #VALUE! | B11: =IF(A11=0,B10,A11) -> #VALUE! | C11: =Black_deaths!E11-White_deaths!E11 -> #VALUE! | D11: =IF(C11=0,D10,C11) -> #VALUE! | E11: =Black_deaths!G11-White_deaths!G11 -> #VALUE! | F11: =IF(E11=0,F10,E11) -> #VALUE! | G11: =Black_deaths!I11-White_deaths!I11 -> #VALUE! | H11: =IF(G11=0,H10,G11) -> #VALUE! | I11: =Black_deaths!K11-White_deaths!K11 -> -2 | J11: =IF(I11=0,J10,I11) -> -2
A12: =Black_deaths!C12-White_deaths!C12 -> #VALUE! | B12: =IF(A12=0,B11,A12) -> #VALUE! | C12: =Black_deaths!E12-White_deaths!E12 -> #VALUE! | D12: =IF(C12=0,D11,C12) -> #VALUE! | E12: =Black_deaths!G12-White_deaths!G12 -> #VALUE! | F12: =IF(E12=0,F11,E12) -> #VALUE! | G12: =Black_deaths!I12-White_deaths!I12 -> -33 | H12: =IF(G12=0,H11,G12) -> -33 | I12: =Black_deaths!K12-White_deaths!K12 -> -33 | J12: =I12 -> -33
A13: =Black_deaths!C13-White_deaths!C13 -> #VALUE! | B13: =IF(A13=0,B12,A13) -> #VALUE! | C13: =Black_deaths!E13-White_deaths!E13 -> #VALUE! | D13: =IF(C13=0,D12,C13) -> #VALUE! | E13: =Black_deaths!G13-White_deaths!G13 -> #VALUE! | F13: =IF(E13=0,F12,E13) -> #VALUE! | G13: =Black_deaths!I13-White_deaths!I13 -> #VALUE! | H13: =IF(G13=0,H12,G13) -> #VALUE! | I13: =Black_deaths!K13-White_deaths!K13 -> -1 | J13: =IF(I13=0,J12,I13) -> -1
A14: =Black_deaths!C14-White_deaths!C14 -> #VALUE! | B14: =IF(A14=0,B13,A14) -> #VALUE! | C14: =Black_deaths!E14-White_deaths!E14 -> -30 | D14: =IF(C14=0,D13,C14) -> -30 | E14: =Black_deaths!G14-White_deaths!G14 -> -55 | F14: =IF(E14=0,F13,E14) -> -55 | G14: =Black_deaths!I14-White_deaths!I14 -> -55 | H14: =IF(G14=0,H13,G14) -> -55 | I14: =Black_deaths!K14-White_deaths!K14 -> -55 | J14: =I14 -> -55
A15: =Black_deaths!C15-White_deaths!C15 -> #VALUE! | B15: =IF(A15=0,B14,A15) -> #VALUE! | C15: =Black_deaths!E15-White_deaths!E15 -> #VALUE! | D15: =IF(C15=0,D14,C15) -> #VALUE! | E15: =Black_deaths!G15-White_deaths!G15 -> #VALUE! | F15: =IF(E15=0,F14,E15) -> #VALUE! | G15: =Black_deaths!I15-White_deaths!I15 -> #VALUE! | H15: =IF(G15=0,H14,G15) -> #VALUE! | I15: =Black_deaths!K15-White_deaths!K15 -> -9 | J15: =IF(I15=0,J14,I15) -> -9
A16: =Black_deaths!C16-White_deaths!C16 -> #VALUE! | B16: =IF(A16=0,B15,A16) -> #VALUE! | C16: =Black_deaths!E16-White_deaths!E16 -> #VALUE! | D16: =IF(C16=0,D15,C16) -> #VALUE! | E16: =Black_deaths!G16-White_deaths!G16 -> #VALUE! | F16: =IF(E16=0,F15,E16) -> #VALUE! | G16: =Black_deaths!I16-White_deaths!I16 -> -57 | H16: =IF(G16=0,H15,G16) -> -57 | I16: =Black_deaths!K16-White_deaths!K16 -> -57 | J16: =I16 -> -57
A17: =Black_deaths!C17-White_deaths!C17 -> #VALUE! | B17: =IF(A17=0,B16,A17) -> #VALUE! | C17: =Black_deaths!E17-White_deaths!E17 -> #VALUE! | D17: =IF(C17=0,D16,C17) -> #VALUE! | E17: =Black_deaths!G17-White_deaths!G17 -> #VALUE! | F17: =IF(E17=0,F16,E17) -> #VALUE! | G17: =Black_deaths!I17-White_deaths!I17 -> #VALUE! | H17: =IF(G17=0,H16,G17) -> #VALUE! | I17: =Black_deaths!K17-White_deaths!K17 -> -7 | J17: =IF(I17=0,J16,I17) -> -7
A18: =Black_deaths!C18-White_deaths!C18 -> #VALUE! | B18: =IF(A18=0,B17,A18) -> #VALUE! | C18: =Black_deaths!E18-White_deaths!E18 -> #VALUE! | D18: =IF(C18=0,D17,C18) -> #VALUE! | E18: =Black_deaths!G18-White_deaths!G18 -> -30 | F18: =IF(E18=0,F17,E18) -> -30 | G18: =Black_deaths!I18-White_deaths!I18 -> -30 | H18: =IF(G18=0,H17,G18) -> -30 | I18: =Black_deaths!K18-White_deaths!K18 -> -30 | J18: =I18 -> -30
A19: =Black_deaths!C19-White_deaths!C19 -> #VALUE! | B19: =IF(A19=0,B18,A19) -> #VALUE! | C19: =Black_deaths!E19-White_deaths!E19 -> #VALUE! | D19: =IF(C19=0,D18,C19) -> #VALUE! | E19: =Black_deaths!G19-White_deaths!G19 -> #VALUE! | F19: =IF(E19=0,F18,E19) -> #VALUE! | G19: =Black_deaths!I19-White_deaths!I19 -> #VALUE! | H19: =IF(G19=0,H18,G19) -> #VALUE! | I19: =Black_deaths!K19-White_deaths!K19 -> -5 | J19: =IF(I19=0,J18,I19) -> -5
A20: =Black_deaths!C20-White_deaths!C20 -> #VALUE! | B20: =IF(A20=0,B19,A20) -> #VALUE! | C20: =Black_deaths!E20-White_deaths!E20 -> #VALUE! | D20: =IF(C20=0,D19,C20) -> #VALUE! | E20: =Black_deaths!G20-White_deaths!G20 -> #VALUE! | F20: =IF(E20=0,F19,E20) -> #VALUE! | G20: =Black_deaths!I20-White_deaths!I20 -> -31 | H20: =IF(G20=0,H19,G20) -> -31 | I20: =Black_deaths!K20-White_deaths!K20 -> -31 | J20: =I20 -> -31
A21: =Black_deaths!C21-White_deaths!C21 -> #VALUE! | B21: =IF(A21=0,B20,A21) -> #VALUE! | C21: =Black_deaths!E21-White_deaths!E21 -> #VALUE! | D21: =IF(C21=0,D20,C21) -> #VALUE! | E21: =Black_deaths!G21-White_deaths!G21 -> #VALUE! | F21: =IF(E21=0,F20,E21) -> #VALUE! | G21: =Black_deaths!I21-White_deaths!I21 -> #VALUE! | H21: =IF(G21=0,H20,G21) -> #VALUE! | I21: =Black_deaths!K21-White_deaths!K21 -> -4 | J21: =IF(I21=0,J20,I21) -> -4
A22: =Black_deaths!C22-White_deaths!C22 -> #VALUE! | B22: =IF(A22=0,B21,A22) -> #VALUE! | C22: =Black_deaths!E22-White_deaths!E22 -> #VALUE! | D22: =IF(C22=0,D21,C22) -> #VALUE! | E22: =Black_deaths!G22-White_deaths!G22 -> -31 | F22: =IF(E22=0,F21,E22) -> -31 | G22: =Black_deaths!I22-White_deaths!I22 -> -31 | H22: =IF(G22=0,H21,G22) -> -31 | I22: =Black_deaths!K22-White_deaths!K22 -> -31 | J22: =I22 -> -31
A23: =Black_deaths!C23-White_deaths!C23 -> #VALUE! | B23: =IF(A23=0,B22,A23) -> #VALUE! | C23: =Black_deaths!E23-White_deaths!E23 -> #VALUE! | D23: =IF(C23=0,D22,C23) -> #VALUE! | E23: =Black_deaths!G23-White_deaths!G23 -> #VALUE! | F23: =IF(E23=0,F22,E23) -> #VALUE! | G23: =Black_deaths!I23-White_deaths!I23 -> #VALUE! | H23: =IF(G23=0,H22,G23) -> #VALUE! | I23: =Black_deaths!K23-White_deaths!K23 -> -6 | J23: =IF(I23=0,J22,I23) -> -6
A24: =Black_deaths!C24-White_deaths!C24 -> #VALUE! | B24: =IF(A24=0,B23,A24) -> #VALUE! | C24: =Black_deaths!E24-White_deaths!E24 -> #VALUE! | D24: =IF(C24=0,D23,C24) -> #VALUE! | E24: =Black_deaths!G24-White_deaths!G24 -> #VALUE! | F24: =IF(E24=0,F23,E24) -> #VALUE! | G24: =Black_deaths!I24-White_deaths!I24 -> -33 | H24: =IF(G24=0,H23,G24) -> -33 | I24: =Black_deaths!K24-White_deaths!K24 -> -33 | J24: =I24 -> -33
A25: =Black_deaths!C25-White_deaths!C25 -> #VALUE! | B25: =IF(A25=0,B24,A25) -> #VALUE! | C25: =Black_deaths!E25-White_deaths!E25 -> #VALUE! | D25: =IF(C25=0,D24,C25) -> #VALUE! | E25: =Black_deaths!G25-White_deaths!G25 -> #VALUE! | F25: =IF(E25=0,F24,E25) -> #VALUE! | G25: =Black_deaths!I25-White_deaths!I25 -> #VALUE! | H25: =IF(G25=0,H24,G25) -> #VALUE! | I25: =Black_deaths!K25-White_deaths!K25 -> -5 | J25: =IF(I25=0,J24,I25) -> -5
A26: =Black_deaths!C26-White_deaths!C26 -> -26 | B26: =IF(A26=0,B25,A26) -> -26 | C26: =Black_deaths!E26-White_deaths!E26 -> -26 | D26: =IF(C26=0,D25,C26) -> -26 | E26: =Black_deaths!G26-White_deaths!G26 -> -44 | F26: =IF(E26=0,F25,E26) -> -44 | G26: =Black_deaths!I26-White_deaths!I26 -> -44 | H26: =IF(G26=0,H25,G26) -> -44 | I26: =Black_deaths!K26-White_deaths!K26 -> -44 | J26: =I26 -> -44
A27: =Black_deaths!C27-White_deaths!C27 -> #VALUE! | B27: =IF(A27=0,B26,A27) -> #VALUE! | C27: =Black_deaths!E27-White_deaths!E27 -> #VALUE! | D27: =IF(C27=0,D26,C27) -> #VALUE! | E27: =Black_deaths!G27-White_deaths!G27 -> #VALUE! | F27: =IF(E27=0,F26,E27) -> #VALUE! | G27: =Black_deaths!I27-White_deaths!I27 -> #VALUE! | H27: =IF(G27=0,H26,G27) -> #VALUE! | I27: =Black_deaths!K27-White_deaths!K27 -> -7 | J27: =IF(I27=0,J26,I27) -> -7
A28: =Black_deaths!C28-White_deaths!C28 -> #VALUE! | B28: =IF(A28=0,B27,A28) -> #VALUE! | C28: =Black_deaths!E28-White_deaths!E28 -> #VALUE! | D28: =IF(C28=0,D27,C28) -> #VALUE! | E28: =Black_deaths!G28-White_deaths!G28 -> #VALUE! | F28: =IF(E28=0,F27,E28) -> #VALUE! | G28: =Black_deaths!I28-White_deaths!I28 -> -45 | H28: =IF(G28=0,H27,G28) -> -45 | I28: =Black_deaths!K28-White_deaths!K28 -> -45 | J28: =I28 -> -45
A29: =Black_deaths!C29-White_deaths!C29 -> #VALUE! | B29: =IF(A29=0,B28,A29) -> #VALUE! | C29: =Black_deaths!E29-White_deaths!E29 -> #VALUE! | D29: =IF(C29=0,D28,C29) -> #VALUE! | E29: =Black_deaths!G29-White_deaths!G29 -> #VALUE! | F29: =IF(E29=0,F28,E29) -> #VALUE! | G29: =Black_deaths!I29-White_deaths!I29 -> #VALUE! | H29: =IF(G29=0,H28,G29) -> #VALUE! | I29: =Black_deaths!K29-White_deaths!K29 -> -3 | J29: =IF(I29=0,J28,I29) -> -3
A30: =Black_deaths!C30-White_deaths!C30 -> #VALUE! | B30: =IF(A30=0,B29,A30) -> #VALUE! | C30: =Black_deaths!E30-White_deaths!E30 -> #VALUE! | D30: =IF(C30=0,D29,C30) -> #VALUE! | E30: =Black_deaths!G30-White_deaths!G30 -> -26 | F30: =IF(E30=0,F29,E30) -> -26 | G30: =Black_deaths!I30-White_deaths!I30 -> -26 | H30: =IF(G30=0,H29,G30) -> -26 | I30: =Black_deaths!K30-White_deaths!K30 -> -26 | J30: =I30 -> -26
A31: =Black_deaths!C31-White_deaths!C31 -> #VALUE! | B31: =IF(A31=0,B30,A31) -> #VALUE! | C31: =Black_deaths!E31-White_deaths!E31 -> #VALUE! | D31: =IF(C31=0,D30,C31) -> #VALUE! | E31: =Black_deaths!G31-White_deaths!G31 -> #VALUE! | F31: =IF(E31=0,F30,E31) -> #VALUE! | G31: =Black_deaths!I31-White_deaths!I31 -> #VALUE! | H31: =IF(G31=0,H30,G31) -> #VALUE! | I31: =Black_deaths!K31-White_deaths!K31 -> -2 | J31: =IF(I31=0,J30,I31) -> -2
A32: =Black_deaths!C32-White_deaths!C32 -> #VALUE! | B32: =IF(A32=0,B31,A32) -> #VALUE! | C32: =Black_deaths!E32-White_deaths!E32 -> #VALUE! | D32: =IF(C32=0,D31,C32) -> #VALUE! | E32: =Black_deaths!G32-White_deaths!G32 -> #VALUE! | F32: =IF(E32=0,F31,E32) -> #VALUE! | G32: =Black_deaths!I32-White_deaths!I32 -> -27 | H32: =IF(G32=0,H31,G32) -> -27 | I32: =Black_deaths!K32-White_deaths!K32 -> -27 | J32: =I32 -> -27
A33: =Black_deaths!C33-White_deaths!C33 -> #VALUE! | B33: =IF(A33=0,B32,A33) -> #VALUE! | C33: =Black_deaths!E33-White_deaths!E33 -> #VALUE! | D33: =IF(C33=0,D32,C33) -> #VALUE! | E33: =Black_deaths!G33-White_deaths!G33 -> #VALUE! | F33: =IF(E33=0,F32,E33) -> #VALUE! | G33: =Black_deaths!I33-White_deaths!I33 -> #VALUE! | H33: =IF(G33=0,H32,G33) -> #VALUE! | I33: =Black_deaths!K33-White_deaths!K33 -> 1 | J33: =IF(I33=0,J32,I33) -> 1
A34: =Black_deaths!C34-White_deaths!C34 -> #VALUE! | B34: =IF(A34=0,B33,A34) -> #VALUE! | C34: =Black_deaths!E34-White_deaths!E34 -> #VALUE! | D34: =IF(C34=0,D33,C34) -> #VALUE! | E34: =Black_deaths!G34-White_deaths!G34 -> -26 | F34: =IF(E34=0,F33,E34) -> -26 | G34: =Black_deaths!I34-White_deaths!I34 -> -26 | H34: =IF(G34=0,H33,G34) -> -26 | I34: =Black_deaths!K34-White_deaths!K34 -> -26 | J34: =I34 -> -26
A35: =Black_deaths!C35-White_deaths!C35 -> #VALUE! | B35: =IF(A35=0,B34,A35) -> #VALUE! | C35: =Black_deaths!E35-White_deaths!E35 -> #VALUE! | D35: =IF(C35=0,D34,C35) -> #VALUE! | E35: =Black_deaths!G35-White_deaths!G35 -> #VALUE! | F35: =IF(E35=0,F34,E35) -> #VALUE! | G35: =Black_deaths!I35-White_deaths!I35 -> #VALUE! | H35: =IF(G35=0,H34,G35) -> #VALUE! | I35: =Black_deaths!K35-White_deaths!K35 -> -2 | J35: =IF(I35=0,J34,I35) -> -2
A36: =Black_deaths!C36-White_deaths!C36 -> #VALUE! | B36: =IF(A36=0,B35,A36) -> #VALUE! | C36: =Black_deaths!E36-White_deaths!E36 -> #VALUE! | D36: =IF(C36=0,D35,C36) -> #VALUE! | E36: =Black_deaths!G36-White_deaths!G36 -> #VALUE! | F36: =IF(E36=0,F35,E36) -> #VALUE! | G36: =Black_deaths!I36-White_deaths!I36 -> -27 | H36: =IF(G36=0,H35,G36) -> -27 | I36: =Black_deaths!K36-White_deaths!K36 -> -27 | J36: =I36 -> -27
A37: =Black_deaths!C37-White_deaths!C37 -> #VALUE! | B37: =IF(A37=0,B36,A37) -> #VALUE! | C37: =Black_deaths!E37-White_deaths!E37 -> #VALUE! | D37: =IF(C37=0,D36,C37) -> #VALUE! | E37: =Black_deaths!G37-White_deaths!G37 -> #VALUE! | F37: =IF(E37=0,F36,E37) -> #VALUE! | G37: =Black_deaths!I37-White_deaths!I37 -> #VALUE! | H37: =IF(G37=0,H36,G37) -> #VALUE! | I37: =Black_deaths!K37-White_deaths!K37 -> 0 | J37: =IF(I37=0,J36,I37) -> -27
A38: =Black_deaths!C38-White_deaths!C38 -> #VALUE! | B38: =IF(A38=0,B37,A38) -> #VALUE! | C38: =Black_deaths!E38-White_deaths!E38 -> -25 | D38: =IF(C38=0,D37,C38) -> -25 | E38: =Black_deaths!G38-White_deaths!G38 -> -44 | F38: =IF(E38=0,F37,E38) -> -44 | G38: =Black_deaths!I38-White_deaths!I38 -> -44 | H38: =IF(G38=0,H37,G38) -> -44 | I38: =Black_deaths!K38-White_deaths!K38 -> -44 | J38: =I38 -> -44
A39: =Black_deaths!C39-White_deaths!C39 -> #VALUE! | B39: =IF(A39=0,B38,A39) -> #VALUE! | C39: =Black_deaths!E39-White_deaths!E39 -> #VALUE! | D39: =IF(C39=0,D38,C39) -> #VALUE! | E39: =Black_deaths!G39-White_deaths!G39 -> #VALUE! | F39: =IF(E39=0,F38,E39) -> #VALUE! | G39: =Black_deaths!I39-White_deaths!I39 -> #VALUE! | H39: =IF(G39=0,H38,G39) -> #VALUE! | I39: =Black_deaths!K39-White_deaths!K39 -> -8 | J39: =IF(I39=0,J38,I39) -> -8
A40: =Black_deaths!C40-White_deaths!C40 -> #VALUE! | B40: =IF(A40=0,B39,A40) -> #VALUE! | C40: =Black_deaths!E40-White_deaths!E40 -> #VALUE! | D40: =IF(C40=0,D39,C40) -> #VALUE! | E40: =Black_deaths!G40-White_deaths!G40 -> #VALUE! | F40: =IF(E40=0,F39,E40) -> #VALUE! | G40: =Black_deaths!I40-White_deaths!I40 -> -45 | H40: =IF(G40=0,H39,G40) -> -45 | I40: =Black_deaths!K40-White_deaths!K40 -> -45 | J40: =I40 -> -45
...

Sheet White_dr
A1: Metrics | B1: Exposed population | D1: Downscaling | F1: AQM | H1: Baseline mortality rates | J1: Relative risks
B2: SSP2 | C2: 249 | D2: Statistical | E2: 249 | F2: WRF-Chem | G2: 400 | H2: Uniform | I2: 400 | J2: Uniform | K2: 400
J3: Different | K3: 418
H4: Different | I4: 419 | J4: Uniform | K4: 419
J5: Different | K5: 438
F6: InMAP | G6: 249 | H6: Uniform | I6: 249 | J6: Uniform | K6: 249
J7: Different | K7: 260
H8: Different | I8: 261 | J8: Uniform | K8: 261
J9: Different | K9: 273
F10: ISRM | G10: 241 | H10: Uniform | I10: 241 | J10: Uniform | K10: 241
J11: Different | K11: 252
H12: Different | I12: 253 | J12: Uniform | K12: 253
J13: Different | K13: 265
D14: Equity | E14: 219 | F14: WRF-Chem | G14: 399 | H14: Uniform | I14: 399 | J14: Uniform | K14: 399
J15: Different | K15: 417
H16: Different | I16: 418 | J16: Uniform | K16: 418
J17: Different | K17: 437
F18: InMAP | G18: 219 | H18: Uniform | I18: 219 | J18: Uniform | K18: 219
J19: Different | K19: 229
H20: Different | I20: 230 | J20: Uniform | K20: 230
J21: Different | K21: 240
F22: ISRM | G22: 227 | H22: Uniform | I22: 227 | J22: Uniform | K22: 227
J23: Different | K23: 238
H24: Different | I24: 238 | J24: Uniform | K24: 238
J25: Different | K25: 249
B26: SSP3 | C26: 241 | D26: Statistical | E26: 241 | F26: WRF-Chem | G26: 387 | H26: Uniform | I26: 387 | J26: Uniform | K26: 387
J27: Different | K27: 404
H28: Different | I28: 405 | J28: Uniform | K28: 405
J29: Different | K29: 423
F30: InMAP | G30: 241 | H30: Uniform | I30: 241 | J30: Uniform | K30: 241
J31: Different | K31: 252
H32: Different | I32: 252 | J32: Uniform | K32: 252
J33: Different | K33: 264
F34: ISRM | G34: 233 | H34: Uniform | I34: 233 | J34: Uniform | K34: 233
J35: Different | K35: 244
H36: Different | I36: 244 | J36: Uniform | K36: 244
J37: Different | K37: 256
D38: Equity | E38: 212 | F38: WRF-Chem | G38: 385 | H38: Uniform | I38: 385 | J38: Uniform | K38: 385
J39: Different | K39: 403
H40: Different | I40: 404 | J40: Uniform | K40: 404
...

Sheet Black_dr
A1: Metrics | B1: Exposed population | D1: Downscaling | F1: AQM | H1: Baseline mortality rates | J1: Relative risks
B2: SSP2 | C2: 267 | D2: Statistical | E2: 267 | F2: WRF-Chem | G2: 408 | H2: Uniform | I2: 408 | J2: Uniform | K2: 408
J3: Different | K3: 1260
H4: Different | I4: 445 | J4: Uniform | K4: 445
J5: Different | K5: 1380
F6: InMAP | G6: 267 | H6: Uniform | I6: 267 | J6: Uniform | K6: 267
J7: Different | K7: 840
H8: Different | I8: 292 | J8: Uniform | K8: 292
J9: Different | K9: 917
F10: ISRM | G10: 257 | H10: Uniform | I10: 257 | J10: Uniform | K10: 257
J11: Different | K11: 807
H12: Different | I12: 280 | J12: Uniform | K12: 280
J13: Different | K13: 881
D14: Equity | E14: 216 | F14: WRF-Chem | G14: 397 | H14: Uniform | I14: 397 | J14: Uniform | K14: 397
J15: Different | K15: 1230
H16: Different | I16: 433 | J16: Uniform | K16: 433
J17: Different | K17: 1340
F18: InMAP | G18: 216 | H18: Uniform | I18: 216 | J18: Uniform | K18: 216
J19: Different | K19: 684
H20: Different | I20: 236 | J20: Uniform | K20: 236
J21: Different | K21: 747
F22: ISRM | G22: 219 | H22: Uniform | I22: 219 | J22: Uniform | K22: 219
J23: Different | K23: 691
H24: Different | I24: 239 | J24: Uniform | K24: 239
J25: Different | K25: 754
B26: SSP3 | C26: 260 | D26: Statistical | E26: 260 | F26: WRF-Chem | G26: 397 | H26: Uniform | I26: 397 | J26: Uniform | K26: 397
J27: Different | K27: 1230
H28: Different | I28: 440 | J28: Uniform | K28: 440
J29: Different | K29: 1360
F30: InMAP | G30: 260 | H30: Uniform | I30: 260 | J30: Uniform | K30: 260
J31: Different | K31: 818
H32: Different | I32: 289 | J32: Uniform | K32: 289
J33: Different | K33: 907
F34: ISRM | G34: 250 | H34: Uniform | I34: 250 | J34: Uniform | K34: 250
J35: Different | K35: 786
H36: Different | I36: 277 | J36: Uniform | K36: 277
J37: Different | K37: 872
D38: Equity | E38: 211 | F38: WRF-Chem | G38: 387 | H38: Uniform | I38: 387 | J38: Uniform | K38: 387
J39: Different | K39: 1200
H40: Different | I40: 428 | J40: Uniform | K40: 428
...

Sheet Disparity_dr
A1: nonWhite_minus_White
A2: =Black_dr!C2-White_dr!C2 -> 18 | B2: =A2 -> 18 | C2: =Black_dr!E2-White_dr!E2 -> 18 | D2: =C2 -> 18 | E2: =Black_dr!G2-White_dr!G2 -> 8 | F2: =E2 -> 8 | G2: =Black_dr!I2-White_dr!I2 -> 8 | H2: =G2 -> 8 | I2: =Black_dr!K2-White_dr!K2 -> 8 | J2: =I2 -> 8
A3: =Black_dr!C3-White_dr!C3 -> 0 | B3: =IF(A3=0,B2,A3) -> 18 | C3: =Black_dr!E3-White_dr!E3 -> 0 | D3: =IF(C3=0,D2,C3) -> 18 | E3: =Black_dr!G3-White_dr!G3 -> #VALUE! | F3: =IF(E3=0,F2,E3) -> #VALUE! | G3: =Black_dr!I3-White_dr!I3 -> #VALUE! | H3: =IF(G3=0,H2,G3) -> #VALUE! | I3: =Black_dr!K3-White_dr!K3 -> 842 | J3: =IF(I3=0,J2,I3) -> 842
A4: =Black_dr!C4-White_dr!C4 -> 0 | B4: =IF(A4=0,B3,A4) -> 18 | C4: =Black_dr!E4-White_dr!E4 -> 0 | D4: =IF(C4=0,D3,C4) -> 18 | E4: =Black_dr!G4-White_dr!G4 -> #VALUE! | F4: =IF(E4=0,F3,E4) -> #VALUE! | G4: =Black_dr!I4-White_dr!I4 -> 26 | H4: =IF(G4=0,H3,G4) -> 26 | I4: =Black_dr!K4-White_dr!K4 -> 26 | J4: =IF(I4=0,J3,I4) -> 26
A5: =Black_dr!C5-White_dr!C5 -> 0 | B5: =IF(A5=0,B4,A5) -> 18 | C5: =Black_dr!E5-White_dr!E5 -> 0 | D5: =IF(C5=0,D4,C5) -> 18 | E5: =Black_dr!G5-White_dr!G5 -> #VALUE! | F5: =IF(E5=0,F4,E5) -> #VALUE! | G5: =Black_dr!I5-White_dr!I5 -> #VALUE! | H5: =IF(G5=0,H4,G5) -> #VALUE! | I5: =Black_dr!K5-White_dr!K5 -> 942 | J5: =IF(I5=0,J4,I5) -> 942
A6: =Black_dr!C6-White_dr!C6 -> 0 | B6: =IF(A6=0,B5,A6) -> 18 | C6: =Black_dr!E6-White_dr!E6 -> 0 | D6: =IF(C6=0,D5,C6) -> 18 | E6: =Black_dr!G6-White_dr!G6 -> 18 | F6: =IF(E6=0,F5,E6) -> 18 | G6: =Black_dr!I6-White_dr!I6 -> 18 | H6: =IF(G6=0,H5,G6) -> 18 | I6: =Black_dr!K6-White_dr!K6 -> 18 | J6: =IF(I6=0,J5,I6) -> 18
A7: =Black_dr!C7-White_dr!C7 -> 0 | B7: =IF(A7=0,B6,A7) -> 18 | C7: =Black_dr!E7-White_dr!E7 -> 0 | D7: =IF(C7=0,D6,C7) -> 18 | E7: =Black_dr!G7-White_dr!G7 -> #VALUE! | F7: =IF(E7=0,F6,E7) -> #VALUE! | G7: =Black_dr!I7-White_dr!I7 -> #VALUE! | H7: =IF(G7=0,H6,G7) -> #VALUE! | I7: =Black_dr!K7-White_dr!K7 -> 580 | J7: =IF(I7=0,J6,I7) -> 580
A8: =Black_dr!C8-White_dr!C8 -> 0 | B8: =IF(A8=0,B7,A8) -> 18 | C8: =Black_dr!E8-White_dr!E8 -> 0 | D8: =IF(C8=0,D7,C8) -> 18 | E8: =Black_dr!G8-White_dr!G8 -> #VALUE! | F8: =IF(E8=0,F7,E8) -> #VALUE! | G8: =Black_dr!I8-White_dr!I8 -> 31 | H8: =IF(G8=0,H7,G8) -> 31 | I8: =Black_dr!K8-White_dr!K8 -> 31 | J8: =IF(I8=0,J7,I8) -> 31
A9: =Black_dr!C9-White_dr!C9 -> 0 | B9: =IF(A9=0,B8,A9) -> 18 | C9: =Black_dr!E9-White_dr!E9 -> 0 | D9: =IF(C9=0,D8,C9) -> 18 | E9: =Black_dr!G9-White_dr!G9 -> #VALUE! | F9: =IF(E9=0,F8,E9) -> #VALUE! | G9: =Black_dr!I9-White_dr!I9 -> #VALUE! | H9: =IF(G9=0,H8,G9) -> #VALUE! | I9: =Black_dr!K9-White_dr!K9 -> 644 | J9: =IF(I9=0,J8,I9) -> 644
A10: =Black_dr!C10-White_dr!C10 -> 0 | B10: =IF(A10=0,B9,A10) -> 18 | C10: =Black_dr!E10-White_dr!E10 -> 0 | D10: =IF(C10=0,D9,C10) -> 18 | E10: =Black_dr!G10-White_dr!G10 -> 16 | F10: =IF(E10=0,F9,E10) -> 16 | G10: =Black_dr!I10-White_dr!I10 -> 16 | H10: =IF(G10=0,H9,G10) -> 16 | I10: =Black_dr!K10-White_dr!K10 -> 16 | J10: =IF(I10=0,J9,I10) -> 16
A11: =Black_dr!C11-White_dr!C11 -> 0 | B11: =IF(A11=0,B10,A11) -> 18 | C11: =Black_dr!E11-White_dr!E11 -> 0 | D11: =IF(C11=0,D10,C11) -> 18 | E11: =Black_dr!G11-White_dr!G11 -> #VALUE! | F11: =IF(E11=0,F10,E11) -> #VALUE! | G11: =Black_dr!I11-White_dr!I11 -> #VALUE! | H11: =IF(G11=0,H10,G11) -> #VALUE! | I11: =Black_dr!K11-White_dr!K11 -> 555 | J11: =IF(I11=0,J10,I11) -> 555
A12: =Black_dr!C12-White_dr!C12 -> 0 | B12: =IF(A12=0,B11,A12) -> 18 | C12: =Black_dr!E12-White_dr!E12 -> 0 | D12: =IF(C12=0,D11,C12) -> 18 | E12: =Black_dr!G12-White_dr!G12 -> #VALUE! | F12: =IF(E12=0,F11,E12) -> #VALUE! | G12: =Black_dr!I12-White_dr!I12 -> 27 | H12: =IF(G12=0,H11,G12) -> 27 | I12: =Black_dr!K12-White_dr!K12 -> 27 | J12: =IF(I12=0,J11,I12) -> 27
A13: =Black_dr!C13-White_dr!C13 -> 0 | B13: =IF(A13=0,B12,A13) -> 18 | C13: =Black_dr!E13-White_dr!E13 -> 0 | D13: =IF(C13=0,D12,C13) -> 18 | E13: =Black_dr!G13-White_dr!G13 -> #VALUE! | F13: =IF(E13=0,F12,E13) -> #VALUE! | G13: =Black_dr!I13-White_dr!I13 -> #VALUE! | H13: =IF(G13=0,H12,G13) -> #VALUE! | I13: =Black_dr!K13-White_dr!K13 -> 616 | J13: =IF(I13=0,J12,I13) -> 616
A14: =Black_dr!C14-White_dr!C14 -> 0 | B14: =IF(A14=0,B13,A14) -> 18 | C14: =Black_dr!E14-White_dr!E14 -> -3 | D14: =IF(C14=0,D13,C14) -> -3 | E14: =Black_dr!G14-White_dr!G14 -> -2 | F14: =IF(E14=0,F13,E14) -> -2 | G14: =Black_dr!I14-White_dr!I14 -> -2 | H14: =IF(G14=0,H13,G14) -> -2 | I14: =Black_dr!K14-White_dr!K14 -> -2 | J14: =IF(I14=0,J13,I14) -> -2
... A73: =Black_dr!C73-White_dr!C73 -> 0 | B73: =IF(A73=0,B72,A73) -> 17 | C73: =Black_dr!E73-White_dr!E73 -> 0 | D73: =IF(C73=0,D72,C73) -> -4 | E73: =Black_dr!G73-White_dr!G73 -> #VALUE! | F73: =IF(E73=0,F72,E73) -> #VALUE! | G73: =Black_dr!I73-White_dr!I73 -> #VALUE! | H73: =IF(G73=0,H72,G73) -> #VALUE! | I73: =Black_dr!K73-White_dr!K73 -> 506 | J73: =IF(I73=0,J72,I73) -> 506
